# Generated by Minecraft Architect Agent v1
# Run with: /function architect:build
fill ~ ~ ~ ~14 ~ ~12 minecraft:stone_bricks
fill ~ ~1 ~ ~14 ~10 ~ minecraft:white_concrete
fill ~ ~1 ~12 ~14 ~10 ~12 minecraft:white_concrete
fill ~ ~1 ~ ~ ~10 ~12 minecraft:white_concrete
fill ~14 ~1 ~ ~14 ~10 ~12 minecraft:white_concrete
fill ~ ~1 ~ ~ ~11 ~ minecraft:stripped_dark_oak_log
fill ~ ~1 ~12 ~ ~11 ~12 minecraft:stripped_dark_oak_log
fill ~14 ~1 ~ ~14 ~11 ~ minecraft:stripped_dark_oak_log
fill ~14 ~1 ~12 ~14 ~11 ~12 minecraft:stripped_dark_oak_log
fill ~ ~6 ~ ~14 ~6 ~ minecraft:stripped_dark_oak_log
fill ~ ~6 ~12 ~14 ~6 ~12 minecraft:stripped_dark_oak_log
fill ~ ~6 ~ ~ ~6 ~12 minecraft:stripped_dark_oak_log
fill ~14 ~6 ~ ~14 ~6 ~12 minecraft:stripped_dark_oak_log
fill ~ ~10 ~ ~14 ~10 ~ minecraft:stripped_dark_oak_log
fill ~ ~10 ~12 ~14 ~10 ~12 minecraft:stripped_dark_oak_log
fill ~ ~10 ~ ~ ~10 ~12 minecraft:stripped_dark_oak_log
fill ~14 ~10 ~ ~14 ~10 ~12 minecraft:stripped_dark_oak_log
fill ~1 ~1 ~1 ~13 ~1 ~11 minecraft:spruce_planks
fill ~1 ~6 ~1 ~13 ~6 ~11 minecraft:spruce_planks
fill ~-2 ~11 ~-2 ~16 ~11 ~14 minecraft:deepslate_tiles
fill ~-1 ~12 ~-1 ~15 ~12 ~13 minecraft:deepslate_tiles
fill ~ ~13 ~ ~14 ~13 ~12 minecraft:deepslate_tiles
fill ~1 ~14 ~1 ~13 ~14 ~11 minecraft:deepslate_tiles
fill ~2 ~15 ~2 ~12 ~15 ~10 minecraft:deepslate_tiles
fill ~-2 ~11 ~-2 ~16 ~11 ~-2 minecraft:stripped_dark_oak_log
fill ~-2 ~11 ~14 ~16 ~11 ~14 minecraft:stripped_dark_oak_log
fill ~-2 ~11 ~-2 ~-2 ~11 ~14 minecraft:stripped_dark_oak_log
fill ~16 ~11 ~-2 ~16 ~11 ~14 minecraft:stripped_dark_oak_log
setblock ~-2 ~12 ~-2 minecraft:dark_oak_planks
setblock ~16 ~12 ~-2 minecraft:dark_oak_planks
setblock ~-2 ~12 ~14 minecraft:dark_oak_planks
setblock ~16 ~12 ~14 minecraft:dark_oak_planks
fill ~4 ~2 ~ ~5 ~3 ~ minecraft:glass_pane
fill ~3 ~1 ~ ~6 ~1 ~ minecraft:stripped_dark_oak_log
fill ~3 ~4 ~ ~6 ~4 ~ minecraft:stripped_dark_oak_log
fill ~4 ~2 ~12 ~5 ~3 ~12 minecraft:glass_pane
fill ~3 ~1 ~12 ~6 ~1 ~12 minecraft:stripped_dark_oak_log
fill ~3 ~4 ~12 ~6 ~4 ~12 minecraft:stripped_dark_oak_log
fill ~10 ~2 ~ ~11 ~3 ~ minecraft:glass_pane
fill ~9 ~1 ~ ~12 ~1 ~ minecraft:stripped_dark_oak_log
fill ~9 ~4 ~ ~12 ~4 ~ minecraft:stripped_dark_oak_log
fill ~10 ~2 ~12 ~11 ~3 ~12 minecraft:glass_pane
fill ~9 ~1 ~12 ~12 ~1 ~12 minecraft:stripped_dark_oak_log
fill ~9 ~4 ~12 ~12 ~4 ~12 minecraft:stripped_dark_oak_log
fill ~ ~2 ~4 ~ ~3 ~5 minecraft:glass_pane
fill ~ ~1 ~3 ~ ~1 ~6 minecraft:stripped_dark_oak_log
fill ~ ~4 ~3 ~ ~4 ~6 minecraft:stripped_dark_oak_log
fill ~14 ~2 ~4 ~14 ~3 ~5 minecraft:glass_pane
fill ~14 ~1 ~3 ~14 ~1 ~6 minecraft:stripped_dark_oak_log
fill ~14 ~4 ~3 ~14 ~4 ~6 minecraft:stripped_dark_oak_log
fill ~4 ~7 ~ ~5 ~8 ~ minecraft:glass_pane
fill ~3 ~6 ~ ~6 ~6 ~ minecraft:stripped_dark_oak_log
fill ~3 ~9 ~ ~6 ~9 ~ minecraft:stripped_dark_oak_log
fill ~4 ~7 ~12 ~5 ~8 ~12 minecraft:glass_pane
fill ~3 ~6 ~12 ~6 ~6 ~12 minecraft:stripped_dark_oak_log
fill ~3 ~9 ~12 ~6 ~9 ~12 minecraft:stripped_dark_oak_log
fill ~10 ~7 ~ ~11 ~8 ~ minecraft:glass_pane
fill ~9 ~6 ~ ~12 ~6 ~ minecraft:stripped_dark_oak_log
fill ~9 ~9 ~ ~12 ~9 ~ minecraft:stripped_dark_oak_log
fill ~10 ~7 ~12 ~11 ~8 ~12 minecraft:glass_pane
fill ~9 ~6 ~12 ~12 ~6 ~12 minecraft:stripped_dark_oak_log
fill ~9 ~9 ~12 ~12 ~9 ~12 minecraft:stripped_dark_oak_log
fill ~ ~7 ~4 ~ ~8 ~5 minecraft:glass_pane
fill ~ ~6 ~3 ~ ~6 ~6 minecraft:stripped_dark_oak_log
fill ~ ~9 ~3 ~ ~9 ~6 minecraft:stripped_dark_oak_log
fill ~14 ~7 ~4 ~14 ~8 ~5 minecraft:glass_pane
fill ~14 ~6 ~3 ~14 ~6 ~6 minecraft:stripped_dark_oak_log
fill ~14 ~9 ~3 ~14 ~9 ~6 minecraft:stripped_dark_oak_log
fill ~6 ~12 ~13 ~8 ~13 ~13 minecraft:glass_pane
fill ~5 ~11 ~13 ~9 ~11 ~13 minecraft:stripped_dark_oak_log
fill ~6 ~1 ~12 ~8 ~3 ~12 minecraft:air
fill ~6 ~3 ~12 ~8 ~3 ~12 minecraft:stripped_dark_oak_log
setblock ~7 ~1 ~12 minecraft:spruce_door[facing=south,half=lower,hinge=left]
setblock ~7 ~2 ~12 minecraft:spruce_door[facing=south,half=upper,hinge=left]
fill ~6 ~ ~13 ~8 ~ ~13 minecraft:mossy_cobblestone
setblock ~6 ~2 ~13 minecraft:lantern[hanging=true]
setblock ~8 ~2 ~13 minecraft:lantern[hanging=true]
fill ~4 ~1 ~13 ~10 ~1 ~15 minecraft:spruce_planks
fill ~3 ~1 ~13 ~3 ~3 ~15 minecraft:stripped_dark_oak_log
fill ~11 ~1 ~13 ~11 ~3 ~15 minecraft:stripped_dark_oak_log
fill ~3 ~4 ~13 ~11 ~4 ~15 minecraft:dark_oak_planks
setblock ~5 ~2 ~15 minecraft:lantern[hanging=true]
setblock ~9 ~2 ~15 minecraft:lantern[hanging=true]
fill ~7 ~2 ~3 ~7 ~4 ~9 minecraft:birch_planks
fill ~7 ~2 ~5 ~7 ~3 ~7 minecraft:air
fill ~3 ~2 ~6 ~11 ~4 ~6 minecraft:birch_planks
fill ~6 ~2 ~6 ~8 ~3 ~6 minecraft:air
fill ~7 ~7 ~3 ~7 ~9 ~9 minecraft:birch_planks
fill ~7 ~7 ~5 ~7 ~8 ~7 minecraft:air
fill ~3 ~7 ~6 ~11 ~9 ~6 minecraft:birch_planks
fill ~6 ~7 ~6 ~8 ~8 ~6 minecraft:air
fill ~3 ~6 ~4 ~6 ~6 ~9 minecraft:air
setblock ~3 ~2 ~4 minecraft:spruce_stairs[facing=south,half=bottom]
setblock ~3 ~3 ~5 minecraft:spruce_stairs[facing=south,half=bottom]
setblock ~4 ~4 ~6 minecraft:spruce_stairs[facing=south,half=bottom]
setblock ~4 ~5 ~7 minecraft:spruce_stairs[facing=south,half=bottom]
setblock ~5 ~6 ~8 minecraft:spruce_stairs[facing=south,half=bottom]
setblock ~2 ~2 ~2 minecraft:bookshelf
setblock ~5 ~2 ~4 minecraft:crafting_table
fill ~2 ~2 ~2 ~4 ~2 ~4 minecraft:green_carpet
setblock ~3 ~5 ~3 minecraft:lantern[hanging=true]
setblock ~9 ~2 ~4 minecraft:furnace[facing=north]
setblock ~10 ~2 ~4 minecraft:crafting_table
fill ~9 ~2 ~2 ~11 ~2 ~4 minecraft:light_gray_carpet
setblock ~10 ~5 ~3 minecraft:lantern[hanging=true]
setblock ~5 ~2 ~8 minecraft:red_bed[facing=south]
setblock ~4 ~2 ~8 minecraft:chest[facing=south]
fill ~2 ~2 ~8 ~4 ~2 ~10 minecraft:red_carpet
setblock ~3 ~5 ~9 minecraft:lantern[hanging=true]
setblock ~9 ~2 ~8 minecraft:bookshelf
setblock ~10 ~2 ~8 minecraft:lectern[facing=south]
fill ~9 ~2 ~8 ~11 ~2 ~10 minecraft:green_carpet
setblock ~10 ~5 ~9 minecraft:lantern[hanging=true]
setblock ~2 ~7 ~2 minecraft:bookshelf
setblock ~5 ~7 ~4 minecraft:crafting_table
fill ~2 ~7 ~2 ~4 ~7 ~4 minecraft:green_carpet
setblock ~3 ~10 ~3 minecraft:lantern[hanging=true]
setblock ~12 ~7 ~2 minecraft:red_bed[facing=south]
setblock ~11 ~7 ~2 minecraft:chest[facing=south]
fill ~9 ~7 ~2 ~11 ~7 ~4 minecraft:red_carpet
setblock ~10 ~10 ~3 minecraft:lantern[hanging=true]
setblock ~2 ~7 ~10 minecraft:furnace[facing=north]
setblock ~3 ~7 ~10 minecraft:crafting_table
fill ~2 ~7 ~8 ~4 ~7 ~10 minecraft:light_gray_carpet
setblock ~3 ~10 ~9 minecraft:lantern[hanging=true]
setblock ~9 ~7 ~10 minecraft:furnace[facing=north]
setblock ~10 ~7 ~10 minecraft:crafting_table
fill ~9 ~7 ~8 ~11 ~7 ~10 minecraft:light_gray_carpet
setblock ~10 ~10 ~9 minecraft:lantern[hanging=true]
fill ~6 ~ ~13 ~8 ~ ~18 minecraft:mossy_cobblestone
fill ~-3 ~ ~14 ~-3 ~1 ~18 minecraft:azalea_leaves[persistent=true]
fill ~17 ~ ~14 ~17 ~1 ~18 minecraft:azalea_leaves[persistent=true]
fill ~-3 ~ ~18 ~17 ~1 ~18 minecraft:azalea_leaves[persistent=true]
fill ~2 ~ ~15 ~5 ~ ~17 minecraft:grass_block
fill ~9 ~ ~15 ~12 ~ ~17 minecraft:grass_block
setblock ~3 ~1 ~15 minecraft:blue_orchid
setblock ~11 ~1 ~15 minecraft:poppy
setblock ~3 ~1 ~17 minecraft:blue_orchid
setblock ~11 ~1 ~17 minecraft:poppy
fill ~11 ~ ~16 ~15 ~ ~19 minecraft:stone_bricks
fill ~12 ~1 ~17 ~14 ~1 ~18 minecraft:water
setblock ~13 ~2 ~17 minecraft:lantern[hanging=true]
